[2022-07-18 12:45:49,838] {taskinstance.py:1179} INFO - Dependencies all met for <TaskInstance: etl_dag.extract manual__2022-07-18T12:45:48.189121+00:00 [queued]>
[2022-07-18 12:45:49,848] {taskinstance.py:1179} INFO - Dependencies all met for <TaskInstance: etl_dag.extract manual__2022-07-18T12:45:48.189121+00:00 [queued]>
[2022-07-18 12:45:49,848] {taskinstance.py:1376} INFO - 
--------------------------------------------------------------------------------
[2022-07-18 12:45:49,848] {taskinstance.py:1377} INFO - Starting attempt 1 of 1
[2022-07-18 12:45:49,848] {taskinstance.py:1378} INFO - 
--------------------------------------------------------------------------------
[2022-07-18 12:45:49,864] {taskinstance.py:1397} INFO - Executing <Task(PythonOperator): extract> on 2022-07-18 12:45:48.189121+00:00
[2022-07-18 12:45:49,870] {standard_task_runner.py:52} INFO - Started process 674 to run task
[2022-07-18 12:45:49,874] {standard_task_runner.py:79} INFO - Running: ['***', 'tasks', 'run', 'etl_dag', 'extract', 'manual__2022-07-18T12:45:48.189121+00:00', '--job-id', '5', '--raw', '--subdir', 'DAGS_FOLDER/etl_dag.py', '--cfg-path', '/tmp/tmpax3zu_6f', '--error-file', '/tmp/tmphucp3epd']
[2022-07-18 12:45:49,875] {standard_task_runner.py:80} INFO - Job 5: Subtask extract
[2022-07-18 12:45:49,948] {task_command.py:371} INFO - Running <TaskInstance: etl_dag.extract manual__2022-07-18T12:45:48.189121+00:00 [running]> on host 2a03843e0228
[2022-07-18 12:45:50,039] {taskinstance.py:1591} INFO - Exporting the following env vars:
AIRFLOW_CTX_DAG_OWNER=***
AIRFLOW_CTX_DAG_ID=etl_dag
AIRFLOW_CTX_TASK_ID=extract
AIRFLOW_CTX_EXECUTION_DATE=2022-07-18T12:45:48.189121+00:00
AIRFLOW_CTX_TRY_NUMBER=1
AIRFLOW_CTX_DAG_RUN_ID=manual__2022-07-18T12:45:48.189121+00:00
[2022-07-18 12:45:50,040] {logging_mixin.py:115} INFO - extracting
[2022-07-18 12:45:50,902] {taskinstance.py:1909} ERROR - Task failed with exception
Traceback (most recent call last):
  File "/home/airflow/.local/lib/python3.7/site-packages/airflow/operators/python.py", line 171, in execute
    return_value = self.execute_callable()
  File "/home/airflow/.local/lib/python3.7/site-packages/airflow/operators/python.py", line 189, in execute_callable
    return self.python_callable(*self.op_args, **self.op_kwargs)
  File "/opt/airflow/dags/etl_dag.py", line 69, in extract
    for song in data["items"]:
KeyError: 'items'
[2022-07-18 12:45:50,932] {taskinstance.py:1420} INFO - Marking task as FAILED. dag_id=etl_dag, task_id=extract, execution_date=20220718T124548, start_date=20220718T124549, end_date=20220718T124550
[2022-07-18 12:45:50,970] {standard_task_runner.py:97} ERROR - Failed to execute job 5 for task extract ('items'; 674)
[2022-07-18 12:45:51,008] {local_task_job.py:156} INFO - Task exited with return code 1
[2022-07-18 12:45:51,056] {local_task_job.py:273} INFO - 0 downstream tasks scheduled from follow-on schedule check
