[2022-07-18 12:51:28,396] {taskinstance.py:1179} INFO - Dependencies all met for <TaskInstance: etl_dag.extract manual__2022-07-18T12:51:25.641425+00:00 [queued]>
[2022-07-18 12:51:28,406] {taskinstance.py:1179} INFO - Dependencies all met for <TaskInstance: etl_dag.extract manual__2022-07-18T12:51:25.641425+00:00 [queued]>
[2022-07-18 12:51:28,406] {taskinstance.py:1376} INFO - 
--------------------------------------------------------------------------------
[2022-07-18 12:51:28,406] {taskinstance.py:1377} INFO - Starting attempt 1 of 1
[2022-07-18 12:51:28,406] {taskinstance.py:1378} INFO - 
--------------------------------------------------------------------------------
[2022-07-18 12:51:28,422] {taskinstance.py:1397} INFO - Executing <Task(PythonOperator): extract> on 2022-07-18 12:51:25.641425+00:00
[2022-07-18 12:51:28,427] {standard_task_runner.py:52} INFO - Started process 101 to run task
[2022-07-18 12:51:28,429] {standard_task_runner.py:79} INFO - Running: ['***', 'tasks', 'run', 'etl_dag', 'extract', 'manual__2022-07-18T12:51:25.641425+00:00', '--job-id', '9', '--raw', '--subdir', 'DAGS_FOLDER/etl_dag.py', '--cfg-path', '/tmp/tmp1oon_8oo', '--error-file', '/tmp/tmp6hmrb_nx']
[2022-07-18 12:51:28,430] {standard_task_runner.py:80} INFO - Job 9: Subtask extract
[2022-07-18 12:51:28,494] {task_command.py:371} INFO - Running <TaskInstance: etl_dag.extract manual__2022-07-18T12:51:25.641425+00:00 [running]> on host 70b17816bd7e
[2022-07-18 12:51:28,576] {taskinstance.py:1591} INFO - Exporting the following env vars:
AIRFLOW_CTX_DAG_OWNER=***
AIRFLOW_CTX_DAG_ID=etl_dag
AIRFLOW_CTX_TASK_ID=extract
AIRFLOW_CTX_EXECUTION_DATE=2022-07-18T12:51:25.641425+00:00
AIRFLOW_CTX_TRY_NUMBER=1
AIRFLOW_CTX_DAG_RUN_ID=manual__2022-07-18T12:51:25.641425+00:00
[2022-07-18 12:51:28,577] {logging_mixin.py:115} INFO - extracting
[2022-07-18 12:51:29,535] {taskinstance.py:1909} ERROR - Task failed with exception
Traceback (most recent call last):
  File "/home/airflow/.local/lib/python3.7/site-packages/airflow/operators/python.py", line 171, in execute
    return_value = self.execute_callable()
  File "/home/airflow/.local/lib/python3.7/site-packages/airflow/operators/python.py", line 189, in execute_callable
    return self.python_callable(*self.op_args, **self.op_kwargs)
  File "/opt/airflow/dags/etl_dag.py", line 69, in extract
    for song in data["items"]:
KeyError: 'items'
[2022-07-18 12:51:29,546] {taskinstance.py:1420} INFO - Marking task as FAILED. dag_id=etl_dag, task_id=extract, execution_date=20220718T125125, start_date=20220718T125128, end_date=20220718T125129
[2022-07-18 12:51:29,566] {standard_task_runner.py:97} ERROR - Failed to execute job 9 for task extract ('items'; 101)
[2022-07-18 12:51:29,603] {local_task_job.py:156} INFO - Task exited with return code 1
[2022-07-18 12:51:29,664] {local_task_job.py:273} INFO - 0 downstream tasks scheduled from follow-on schedule check
