[2022-07-21 06:28:18,652] {taskinstance.py:1179} INFO - Dependencies all met for <TaskInstance: etl_dag.load scheduled__2022-07-18T00:00:00+00:00 [queued]>
[2022-07-21 06:28:18,666] {taskinstance.py:1179} INFO - Dependencies all met for <TaskInstance: etl_dag.load scheduled__2022-07-18T00:00:00+00:00 [queued]>
[2022-07-21 06:28:18,666] {taskinstance.py:1376} INFO - 
--------------------------------------------------------------------------------
[2022-07-21 06:28:18,666] {taskinstance.py:1377} INFO - Starting attempt 1 of 1
[2022-07-21 06:28:18,666] {taskinstance.py:1378} INFO - 
--------------------------------------------------------------------------------
[2022-07-21 06:28:18,686] {taskinstance.py:1397} INFO - Executing <Task(PythonOperator): load> on 2022-07-18 00:00:00+00:00
[2022-07-21 06:28:18,693] {standard_task_runner.py:52} INFO - Started process 97 to run task
[2022-07-21 06:28:18,698] {standard_task_runner.py:79} INFO - Running: ['***', 'tasks', 'run', 'etl_dag', 'load', 'scheduled__2022-07-18T00:00:00+00:00', '--job-id', '64', '--raw', '--subdir', 'DAGS_FOLDER/etl_dag.py', '--cfg-path', '/tmp/tmptzro7781', '--error-file', '/tmp/tmptdg67r_d']
[2022-07-21 06:28:18,699] {standard_task_runner.py:80} INFO - Job 64: Subtask load
[2022-07-21 06:28:18,782] {task_command.py:371} INFO - Running <TaskInstance: etl_dag.load scheduled__2022-07-18T00:00:00+00:00 [running]> on host 4514cd19035a
[2022-07-21 06:28:18,882] {taskinstance.py:1591} INFO - Exporting the following env vars:
AIRFLOW_CTX_DAG_OWNER=***
AIRFLOW_CTX_DAG_ID=etl_dag
AIRFLOW_CTX_TASK_ID=load
AIRFLOW_CTX_EXECUTION_DATE=2022-07-18T00:00:00+00:00
AIRFLOW_CTX_TRY_NUMBER=1
AIRFLOW_CTX_DAG_RUN_ID=scheduled__2022-07-18T00:00:00+00:00
[2022-07-21 06:28:18,883] {taskinstance.py:1909} ERROR - Task failed with exception
Traceback (most recent call last):
  File "/home/airflow/.local/lib/python3.7/site-packages/airflow/operators/python.py", line 171, in execute
    return_value = self.execute_callable()
  File "/home/airflow/.local/lib/python3.7/site-packages/airflow/operators/python.py", line 189, in execute_callable
    return self.python_callable(*self.op_args, **self.op_kwargs)
  File "/opt/airflow/dags/etl_dag.py", line 99, in load
    if song_dict is not None:
UnboundLocalError: local variable 'song_dict' referenced before assignment
[2022-07-21 06:28:18,893] {taskinstance.py:1420} INFO - Marking task as FAILED. dag_id=etl_dag, task_id=load, execution_date=20220718T000000, start_date=20220721T062818, end_date=20220721T062818
[2022-07-21 06:28:18,910] {standard_task_runner.py:97} ERROR - Failed to execute job 64 for task load (local variable 'song_dict' referenced before assignment; 97)
[2022-07-21 06:28:18,948] {local_task_job.py:156} INFO - Task exited with return code 1
[2022-07-21 06:28:18,996] {local_task_job.py:273} INFO - 0 downstream tasks scheduled from follow-on schedule check
