[2022-07-21 06:28:43,782] {taskinstance.py:1179} INFO - Dependencies all met for <TaskInstance: etl_dag.load manual__2022-07-21T06:28:32.800540+00:00 [queued]>
[2022-07-21 06:28:43,796] {taskinstance.py:1179} INFO - Dependencies all met for <TaskInstance: etl_dag.load manual__2022-07-21T06:28:32.800540+00:00 [queued]>
[2022-07-21 06:28:43,796] {taskinstance.py:1376} INFO - 
--------------------------------------------------------------------------------
[2022-07-21 06:28:43,796] {taskinstance.py:1377} INFO - Starting attempt 1 of 1
[2022-07-21 06:28:43,796] {taskinstance.py:1378} INFO - 
--------------------------------------------------------------------------------
[2022-07-21 06:28:43,817] {taskinstance.py:1397} INFO - Executing <Task(PythonOperator): load> on 2022-07-21 06:28:32.800540+00:00
[2022-07-21 06:28:43,824] {standard_task_runner.py:52} INFO - Started process 129 to run task
[2022-07-21 06:28:43,828] {standard_task_runner.py:79} INFO - Running: ['***', 'tasks', 'run', 'etl_dag', 'load', 'manual__2022-07-21T06:28:32.800540+00:00', '--job-id', '69', '--raw', '--subdir', 'DAGS_FOLDER/etl_dag.py', '--cfg-path', '/tmp/tmpus2u1rbv', '--error-file', '/tmp/tmpnxfuec3p']
[2022-07-21 06:28:43,829] {standard_task_runner.py:80} INFO - Job 69: Subtask load
[2022-07-21 06:28:43,919] {task_command.py:371} INFO - Running <TaskInstance: etl_dag.load manual__2022-07-21T06:28:32.800540+00:00 [running]> on host 4514cd19035a
[2022-07-21 06:28:44,041] {taskinstance.py:1591} INFO - Exporting the following env vars:
AIRFLOW_CTX_DAG_OWNER=***
AIRFLOW_CTX_DAG_ID=etl_dag
AIRFLOW_CTX_TASK_ID=load
AIRFLOW_CTX_EXECUTION_DATE=2022-07-21T06:28:32.800540+00:00
AIRFLOW_CTX_TRY_NUMBER=1
AIRFLOW_CTX_DAG_RUN_ID=manual__2022-07-21T06:28:32.800540+00:00
[2022-07-21 06:28:44,042] {taskinstance.py:1909} ERROR - Task failed with exception
Traceback (most recent call last):
  File "/home/airflow/.local/lib/python3.7/site-packages/airflow/operators/python.py", line 171, in execute
    return_value = self.execute_callable()
  File "/home/airflow/.local/lib/python3.7/site-packages/airflow/operators/python.py", line 189, in execute_callable
    return self.python_callable(*self.op_args, **self.op_kwargs)
  File "/opt/airflow/dags/etl_dag.py", line 99, in load
    if song_dict is not None:
UnboundLocalError: local variable 'song_dict' referenced before assignment
[2022-07-21 06:28:44,051] {taskinstance.py:1420} INFO - Marking task as FAILED. dag_id=etl_dag, task_id=load, execution_date=20220721T062832, start_date=20220721T062843, end_date=20220721T062844
[2022-07-21 06:28:44,066] {standard_task_runner.py:97} ERROR - Failed to execute job 69 for task load (local variable 'song_dict' referenced before assignment; 129)
[2022-07-21 06:28:44,083] {local_task_job.py:156} INFO - Task exited with return code 1
[2022-07-21 06:28:44,130] {local_task_job.py:273} INFO - 0 downstream tasks scheduled from follow-on schedule check
