[2022-07-18 13:06:53,268] {taskinstance.py:1179} INFO - Dependencies all met for <TaskInstance: etl_dag.extract manual__2022-07-18T13:06:51.579880+00:00 [queued]>
[2022-07-18 13:06:53,280] {taskinstance.py:1179} INFO - Dependencies all met for <TaskInstance: etl_dag.extract manual__2022-07-18T13:06:51.579880+00:00 [queued]>
[2022-07-18 13:06:53,280] {taskinstance.py:1376} INFO - 
--------------------------------------------------------------------------------
[2022-07-18 13:06:53,280] {taskinstance.py:1377} INFO - Starting attempt 1 of 1
[2022-07-18 13:06:53,281] {taskinstance.py:1378} INFO - 
--------------------------------------------------------------------------------
[2022-07-18 13:06:53,300] {taskinstance.py:1397} INFO - Executing <Task(PythonOperator): extract> on 2022-07-18 13:06:51.579880+00:00
[2022-07-18 13:06:53,306] {standard_task_runner.py:52} INFO - Started process 801 to run task
[2022-07-18 13:06:53,310] {standard_task_runner.py:79} INFO - Running: ['***', 'tasks', 'run', 'etl_dag', 'extract', 'manual__2022-07-18T13:06:51.579880+00:00', '--job-id', '12', '--raw', '--subdir', 'DAGS_FOLDER/etl_dag.py', '--cfg-path', '/tmp/tmpki2rcpr6', '--error-file', '/tmp/tmp5tcv2z7k']
[2022-07-18 13:06:53,311] {standard_task_runner.py:80} INFO - Job 12: Subtask extract
[2022-07-18 13:06:53,385] {task_command.py:371} INFO - Running <TaskInstance: etl_dag.extract manual__2022-07-18T13:06:51.579880+00:00 [running]> on host 70b17816bd7e
[2022-07-18 13:06:53,472] {taskinstance.py:1591} INFO - Exporting the following env vars:
AIRFLOW_CTX_DAG_OWNER=***
AIRFLOW_CTX_DAG_ID=etl_dag
AIRFLOW_CTX_TASK_ID=extract
AIRFLOW_CTX_EXECUTION_DATE=2022-07-18T13:06:51.579880+00:00
AIRFLOW_CTX_TRY_NUMBER=1
AIRFLOW_CTX_DAG_RUN_ID=manual__2022-07-18T13:06:51.579880+00:00
[2022-07-18 13:06:53,472] {logging_mixin.py:115} INFO - extracting
[2022-07-18 13:06:54,121] {taskinstance.py:1909} ERROR - Task failed with exception
Traceback (most recent call last):
  File "/home/airflow/.local/lib/python3.7/site-packages/airflow/operators/python.py", line 171, in execute
    return_value = self.execute_callable()
  File "/home/airflow/.local/lib/python3.7/site-packages/airflow/operators/python.py", line 189, in execute_callable
    return self.python_callable(*self.op_args, **self.op_kwargs)
  File "/opt/airflow/dags/etl_dag.py", line 70, in extract
    for song in data["items"]:
KeyError: 'items'
[2022-07-18 13:06:54,132] {taskinstance.py:1420} INFO - Marking task as FAILED. dag_id=etl_dag, task_id=extract, execution_date=20220718T130651, start_date=20220718T130653, end_date=20220718T130654
[2022-07-18 13:06:54,150] {standard_task_runner.py:97} ERROR - Failed to execute job 12 for task extract ('items'; 801)
[2022-07-18 13:06:54,162] {local_task_job.py:156} INFO - Task exited with return code 1
[2022-07-18 13:06:54,216] {local_task_job.py:273} INFO - 0 downstream tasks scheduled from follow-on schedule check
