[2022-07-18 13:03:07,652] {taskinstance.py:1179} INFO - Dependencies all met for <TaskInstance: etl_dag.extract manual__2022-07-18T13:03:06.343502+00:00 [queued]>
[2022-07-18 13:03:07,662] {taskinstance.py:1179} INFO - Dependencies all met for <TaskInstance: etl_dag.extract manual__2022-07-18T13:03:06.343502+00:00 [queued]>
[2022-07-18 13:03:07,663] {taskinstance.py:1376} INFO - 
--------------------------------------------------------------------------------
[2022-07-18 13:03:07,663] {taskinstance.py:1377} INFO - Starting attempt 1 of 1
[2022-07-18 13:03:07,663] {taskinstance.py:1378} INFO - 
--------------------------------------------------------------------------------
[2022-07-18 13:03:07,679] {taskinstance.py:1397} INFO - Executing <Task(PythonOperator): extract> on 2022-07-18 13:03:06.343502+00:00
[2022-07-18 13:03:07,685] {standard_task_runner.py:52} INFO - Started process 622 to run task
[2022-07-18 13:03:07,689] {standard_task_runner.py:79} INFO - Running: ['***', 'tasks', 'run', 'etl_dag', 'extract', 'manual__2022-07-18T13:03:06.343502+00:00', '--job-id', '10', '--raw', '--subdir', 'DAGS_FOLDER/etl_dag.py', '--cfg-path', '/tmp/tmplv5_p20p', '--error-file', '/tmp/tmpr1a83gr0']
[2022-07-18 13:03:07,690] {standard_task_runner.py:80} INFO - Job 10: Subtask extract
[2022-07-18 13:03:07,771] {task_command.py:371} INFO - Running <TaskInstance: etl_dag.extract manual__2022-07-18T13:03:06.343502+00:00 [running]> on host 70b17816bd7e
[2022-07-18 13:03:07,866] {taskinstance.py:1591} INFO - Exporting the following env vars:
AIRFLOW_CTX_DAG_OWNER=***
AIRFLOW_CTX_DAG_ID=etl_dag
AIRFLOW_CTX_TASK_ID=extract
AIRFLOW_CTX_EXECUTION_DATE=2022-07-18T13:03:06.343502+00:00
AIRFLOW_CTX_TRY_NUMBER=1
AIRFLOW_CTX_DAG_RUN_ID=manual__2022-07-18T13:03:06.343502+00:00
[2022-07-18 13:03:07,867] {logging_mixin.py:115} INFO - extracting
[2022-07-18 13:03:08,881] {taskinstance.py:1909} ERROR - Task failed with exception
Traceback (most recent call last):
  File "/home/airflow/.local/lib/python3.7/site-packages/airflow/operators/python.py", line 171, in execute
    return_value = self.execute_callable()
  File "/home/airflow/.local/lib/python3.7/site-packages/airflow/operators/python.py", line 189, in execute_callable
    return self.python_callable(*self.op_args, **self.op_kwargs)
  File "/opt/airflow/dags/etl_dag.py", line 70, in extract
    for song in data["items"]:
KeyError: 'items'
[2022-07-18 13:03:08,892] {taskinstance.py:1420} INFO - Marking task as FAILED. dag_id=etl_dag, task_id=extract, execution_date=20220718T130306, start_date=20220718T130307, end_date=20220718T130308
[2022-07-18 13:03:08,909] {standard_task_runner.py:97} ERROR - Failed to execute job 10 for task extract ('items'; 622)
[2022-07-18 13:03:08,942] {local_task_job.py:156} INFO - Task exited with return code 1
[2022-07-18 13:03:08,996] {local_task_job.py:273} INFO - 0 downstream tasks scheduled from follow-on schedule check
