[2022-07-17 19:56:20,886] {taskinstance.py:1179} INFO - Dependencies all met for <TaskInstance: etl_dag.extract scheduled__2022-07-16T00:00:00+00:00 [queued]>
[2022-07-17 19:56:20,896] {taskinstance.py:1179} INFO - Dependencies all met for <TaskInstance: etl_dag.extract scheduled__2022-07-16T00:00:00+00:00 [queued]>
[2022-07-17 19:56:20,896] {taskinstance.py:1376} INFO - 
--------------------------------------------------------------------------------
[2022-07-17 19:56:20,897] {taskinstance.py:1377} INFO - Starting attempt 1 of 1
[2022-07-17 19:56:20,897] {taskinstance.py:1378} INFO - 
--------------------------------------------------------------------------------
[2022-07-17 19:56:20,912] {taskinstance.py:1397} INFO - Executing <Task(PythonOperator): extract> on 2022-07-16 00:00:00+00:00
[2022-07-17 19:56:20,918] {standard_task_runner.py:52} INFO - Started process 940 to run task
[2022-07-17 19:56:20,921] {standard_task_runner.py:79} INFO - Running: ['***', 'tasks', 'run', 'etl_dag', 'extract', 'scheduled__2022-07-16T00:00:00+00:00', '--job-id', '3', '--raw', '--subdir', 'DAGS_FOLDER/etl_dag.py', '--cfg-path', '/tmp/tmpx0cfaqks', '--error-file', '/tmp/tmpb2vqt3p9']
[2022-07-17 19:56:20,923] {standard_task_runner.py:80} INFO - Job 3: Subtask extract
[2022-07-17 19:56:21,010] {task_command.py:371} INFO - Running <TaskInstance: etl_dag.extract scheduled__2022-07-16T00:00:00+00:00 [running]> on host a210108e0bd2
[2022-07-17 19:56:21,095] {taskinstance.py:1591} INFO - Exporting the following env vars:
AIRFLOW_CTX_DAG_OWNER=***
AIRFLOW_CTX_DAG_ID=etl_dag
AIRFLOW_CTX_TASK_ID=extract
AIRFLOW_CTX_EXECUTION_DATE=2022-07-16T00:00:00+00:00
AIRFLOW_CTX_TRY_NUMBER=1
AIRFLOW_CTX_DAG_RUN_ID=scheduled__2022-07-16T00:00:00+00:00
[2022-07-17 19:56:21,097] {taskinstance.py:1909} ERROR - Task failed with exception
Traceback (most recent call last):
  File "/home/airflow/.local/lib/python3.7/site-packages/airflow/operators/python.py", line 171, in execute
    return_value = self.execute_callable()
  File "/home/airflow/.local/lib/python3.7/site-packages/airflow/operators/python.py", line 189, in execute_callable
    return self.python_callable(*self.op_args, **self.op_kwargs)
  File "/opt/airflow/dags/etl_dag.py", line 53, in extract
    today = datetime.datetime.now()
AttributeError: type object 'datetime.datetime' has no attribute 'datetime'
[2022-07-17 19:56:21,107] {taskinstance.py:1420} INFO - Marking task as FAILED. dag_id=etl_dag, task_id=extract, execution_date=20220716T000000, start_date=20220717T195620, end_date=20220717T195621
[2022-07-17 19:56:21,124] {standard_task_runner.py:97} ERROR - Failed to execute job 3 for task extract (type object 'datetime.datetime' has no attribute 'datetime'; 940)
[2022-07-17 19:56:21,172] {local_task_job.py:156} INFO - Task exited with return code 1
[2022-07-17 19:56:21,238] {local_task_job.py:273} INFO - 0 downstream tasks scheduled from follow-on schedule check
