[2022-07-18 05:47:26,857] {taskinstance.py:1179} INFO - Dependencies all met for <TaskInstance: etl_dag.extract scheduled__2022-07-17T00:00:00+00:00 [queued]>
[2022-07-18 05:47:26,871] {taskinstance.py:1179} INFO - Dependencies all met for <TaskInstance: etl_dag.extract scheduled__2022-07-17T00:00:00+00:00 [queued]>
[2022-07-18 05:47:26,871] {taskinstance.py:1376} INFO - 
--------------------------------------------------------------------------------
[2022-07-18 05:47:26,871] {taskinstance.py:1377} INFO - Starting attempt 1 of 1
[2022-07-18 05:47:26,871] {taskinstance.py:1378} INFO - 
--------------------------------------------------------------------------------
[2022-07-18 05:47:26,897] {taskinstance.py:1397} INFO - Executing <Task(PythonOperator): extract> on 2022-07-17 00:00:00+00:00
[2022-07-18 05:47:26,904] {standard_task_runner.py:52} INFO - Started process 67 to run task
[2022-07-18 05:47:26,908] {standard_task_runner.py:79} INFO - Running: ['***', 'tasks', 'run', 'etl_dag', 'extract', 'scheduled__2022-07-17T00:00:00+00:00', '--job-id', '6', '--raw', '--subdir', 'DAGS_FOLDER/etl_dag.py', '--cfg-path', '/tmp/tmpeais5bq2', '--error-file', '/tmp/tmpz9g6wk36']
[2022-07-18 05:47:26,910] {standard_task_runner.py:80} INFO - Job 6: Subtask extract
[2022-07-18 05:47:27,012] {task_command.py:371} INFO - Running <TaskInstance: etl_dag.extract scheduled__2022-07-17T00:00:00+00:00 [running]> on host 94d403a89d15
[2022-07-18 05:47:27,160] {taskinstance.py:1591} INFO - Exporting the following env vars:
AIRFLOW_CTX_DAG_OWNER=***
AIRFLOW_CTX_DAG_ID=etl_dag
AIRFLOW_CTX_TASK_ID=extract
AIRFLOW_CTX_EXECUTION_DATE=2022-07-17T00:00:00+00:00
AIRFLOW_CTX_TRY_NUMBER=1
AIRFLOW_CTX_DAG_RUN_ID=scheduled__2022-07-17T00:00:00+00:00
[2022-07-18 05:47:27,161] {logging_mixin.py:115} INFO - extracting
[2022-07-18 05:47:27,162] {taskinstance.py:1909} ERROR - Task failed with exception
Traceback (most recent call last):
  File "/home/airflow/.local/lib/python3.7/site-packages/airflow/operators/python.py", line 171, in execute
    return_value = self.execute_callable()
  File "/home/airflow/.local/lib/python3.7/site-packages/airflow/operators/python.py", line 189, in execute_callable
    return self.python_callable(*self.op_args, **self.op_kwargs)
  File "/opt/airflow/dags/etl_dag.py", line 53, in extract
    today = datetime.datetime.now()
AttributeError: type object 'datetime.datetime' has no attribute 'datetime'
[2022-07-18 05:47:27,181] {taskinstance.py:1420} INFO - Marking task as FAILED. dag_id=etl_dag, task_id=extract, execution_date=20220717T000000, start_date=20220718T054726, end_date=20220718T054727
[2022-07-18 05:47:27,202] {standard_task_runner.py:97} ERROR - Failed to execute job 6 for task extract (type object 'datetime.datetime' has no attribute 'datetime'; 67)
[2022-07-18 05:47:27,239] {local_task_job.py:156} INFO - Task exited with return code 1
[2022-07-18 05:47:27,321] {local_task_job.py:273} INFO - 0 downstream tasks scheduled from follow-on schedule check
[2022-07-18 12:33:20,964] {taskinstance.py:1179} INFO - Dependencies all met for <TaskInstance: etl_dag.extract scheduled__2022-07-17T00:00:00+00:00 [queued]>
[2022-07-18 12:33:20,974] {taskinstance.py:1179} INFO - Dependencies all met for <TaskInstance: etl_dag.extract scheduled__2022-07-17T00:00:00+00:00 [queued]>
[2022-07-18 12:33:20,974] {taskinstance.py:1376} INFO - 
--------------------------------------------------------------------------------
[2022-07-18 12:33:20,974] {taskinstance.py:1377} INFO - Starting attempt 1 of 1
[2022-07-18 12:33:20,974] {taskinstance.py:1378} INFO - 
--------------------------------------------------------------------------------
[2022-07-18 12:33:20,990] {taskinstance.py:1397} INFO - Executing <Task(PythonOperator): extract> on 2022-07-17 00:00:00+00:00
[2022-07-18 12:33:20,995] {standard_task_runner.py:52} INFO - Started process 110 to run task
[2022-07-18 12:33:20,998] {standard_task_runner.py:79} INFO - Running: ['***', 'tasks', 'run', 'etl_dag', 'extract', 'scheduled__2022-07-17T00:00:00+00:00', '--job-id', '3', '--raw', '--subdir', 'DAGS_FOLDER/etl_dag.py', '--cfg-path', '/tmp/tmphv60t1mu', '--error-file', '/tmp/tmp0yjuumbx']
[2022-07-18 12:33:20,999] {standard_task_runner.py:80} INFO - Job 3: Subtask extract
[2022-07-18 12:33:21,072] {task_command.py:371} INFO - Running <TaskInstance: etl_dag.extract scheduled__2022-07-17T00:00:00+00:00 [running]> on host 2a03843e0228
[2022-07-18 12:33:21,216] {taskinstance.py:1591} INFO - Exporting the following env vars:
AIRFLOW_CTX_DAG_OWNER=***
AIRFLOW_CTX_DAG_ID=etl_dag
AIRFLOW_CTX_TASK_ID=extract
AIRFLOW_CTX_EXECUTION_DATE=2022-07-17T00:00:00+00:00
AIRFLOW_CTX_TRY_NUMBER=1
AIRFLOW_CTX_DAG_RUN_ID=scheduled__2022-07-17T00:00:00+00:00
[2022-07-18 12:33:21,217] {logging_mixin.py:115} INFO - extracting
[2022-07-18 12:33:21,218] {taskinstance.py:1909} ERROR - Task failed with exception
Traceback (most recent call last):
  File "/home/airflow/.local/lib/python3.7/site-packages/airflow/operators/python.py", line 171, in execute
    return_value = self.execute_callable()
  File "/home/airflow/.local/lib/python3.7/site-packages/airflow/operators/python.py", line 189, in execute_callable
    return self.python_callable(*self.op_args, **self.op_kwargs)
  File "/opt/airflow/dags/etl_dag.py", line 53, in extract
    today = datetime.datetime.now()
AttributeError: type object 'datetime.datetime' has no attribute 'datetime'
[2022-07-18 12:33:21,235] {taskinstance.py:1420} INFO - Marking task as FAILED. dag_id=etl_dag, task_id=extract, execution_date=20220717T000000, start_date=20220718T123320, end_date=20220718T123321
[2022-07-18 12:33:21,274] {standard_task_runner.py:97} ERROR - Failed to execute job 3 for task extract (type object 'datetime.datetime' has no attribute 'datetime'; 110)
[2022-07-18 12:33:21,294] {local_task_job.py:156} INFO - Task exited with return code 1
[2022-07-18 12:33:21,391] {local_task_job.py:273} INFO - 0 downstream tasks scheduled from follow-on schedule check
