[2022-07-18 12:36:39,294] {taskinstance.py:1179} INFO - Dependencies all met for <TaskInstance: etl_dag.extract manual__2022-07-18T12:36:38.092931+00:00 [queued]>
[2022-07-18 12:36:39,303] {taskinstance.py:1179} INFO - Dependencies all met for <TaskInstance: etl_dag.extract manual__2022-07-18T12:36:38.092931+00:00 [queued]>
[2022-07-18 12:36:39,303] {taskinstance.py:1376} INFO - 
--------------------------------------------------------------------------------
[2022-07-18 12:36:39,303] {taskinstance.py:1377} INFO - Starting attempt 1 of 1
[2022-07-18 12:36:39,304] {taskinstance.py:1378} INFO - 
--------------------------------------------------------------------------------
[2022-07-18 12:36:39,319] {taskinstance.py:1397} INFO - Executing <Task(PythonOperator): extract> on 2022-07-18 12:36:38.092931+00:00
[2022-07-18 12:36:39,324] {standard_task_runner.py:52} INFO - Started process 257 to run task
[2022-07-18 12:36:39,327] {standard_task_runner.py:79} INFO - Running: ['***', 'tasks', 'run', 'etl_dag', 'extract', 'manual__2022-07-18T12:36:38.092931+00:00', '--job-id', '4', '--raw', '--subdir', 'DAGS_FOLDER/etl_dag.py', '--cfg-path', '/tmp/tmpl_un8jtp', '--error-file', '/tmp/tmpvkqyvqoj']
[2022-07-18 12:36:39,328] {standard_task_runner.py:80} INFO - Job 4: Subtask extract
[2022-07-18 12:36:39,392] {task_command.py:371} INFO - Running <TaskInstance: etl_dag.extract manual__2022-07-18T12:36:38.092931+00:00 [running]> on host 2a03843e0228
[2022-07-18 12:36:39,471] {taskinstance.py:1591} INFO - Exporting the following env vars:
AIRFLOW_CTX_DAG_OWNER=***
AIRFLOW_CTX_DAG_ID=etl_dag
AIRFLOW_CTX_TASK_ID=extract
AIRFLOW_CTX_EXECUTION_DATE=2022-07-18T12:36:38.092931+00:00
AIRFLOW_CTX_TRY_NUMBER=1
AIRFLOW_CTX_DAG_RUN_ID=manual__2022-07-18T12:36:38.092931+00:00
[2022-07-18 12:36:39,473] {logging_mixin.py:115} INFO - extracting
[2022-07-18 12:36:39,473] {taskinstance.py:1909} ERROR - Task failed with exception
Traceback (most recent call last):
  File "/home/airflow/.local/lib/python3.7/site-packages/airflow/operators/python.py", line 171, in execute
    return_value = self.execute_callable()
  File "/home/airflow/.local/lib/python3.7/site-packages/airflow/operators/python.py", line 189, in execute_callable
    return self.python_callable(*self.op_args, **self.op_kwargs)
  File "/opt/airflow/dags/etl_dag.py", line 54, in extract
    yesterday = today - datetime.timedelta(days=1)
AttributeError: type object 'datetime.datetime' has no attribute 'timedelta'
[2022-07-18 12:36:39,482] {taskinstance.py:1420} INFO - Marking task as FAILED. dag_id=etl_dag, task_id=extract, execution_date=20220718T123638, start_date=20220718T123639, end_date=20220718T123639
[2022-07-18 12:36:39,499] {standard_task_runner.py:97} ERROR - Failed to execute job 4 for task extract (type object 'datetime.datetime' has no attribute 'timedelta'; 257)
[2022-07-18 12:36:39,538] {local_task_job.py:156} INFO - Task exited with return code 1
[2022-07-18 12:36:39,624] {local_task_job.py:273} INFO - 0 downstream tasks scheduled from follow-on schedule check
